Workbook

Sheet WBS
B1: Task Description | C1: Deliverable | D1: Estimated Time | E1: Resources
A2: 1 | B2: Program Registration & Attendance Data Hub | C2: Yes | D2: =D4+D10+D17+D22+D29+D34+D39+D44+D49+D51+D56+D64+D69+D73+D80+D84+D88+D92+D96+D101+D104+D107+D113+D120+D126+D131+D133+D136+D143+D149+D153+D160+D165+D170+D175+D178+D182+D186+D190+D192+D196+D201+D206+D209+D212+D220+D224+D230+D241 -> 410
A3: Sprint 0: Initiation and Planning | Sep 24 – Oct 19 (Weeks 1–4) | Complete
A4: 1.1 | B4: SWE 277P Assignment 1: Team Statement (due Oct 6) | C4: Yes | D4: =SUM(D5:D9) -> 15
A5: 1.1.1 | B5: Write the project description | C5: No | D5: 2 | E5: Jennifer Sun
A6: 1.1.2 | B6: Initial team plan: strengths, sponsor questions, learning list | C6: No | D6: 2 | E6: Molly Tran
A7: 1.1.3 | B7: Team ground rules | C7: No | D7: 2 | E7: Brandon Lau
A8: 1.1.4 | B8: Create the shared Google Drive folder and share it with the instructor and TA | C8: No | D8: 1 | E8: Zhenyu Song
A9: 1.1.5 | B9: Team bonding dinner (Oct 6) | C9: No | D9: 8 | E9: All team
A10: 1.2 | B10: Sponsor kickoff and requirements | C10: No | D10: =SUM(D11:D16) -> 18
A11: 1.2.1 | B11: Read the sponsor proposal and the sample exports | C11: No | D11: 3 | E11: Jennifer Sun
A12: 1.2.2 | B12: Prepare questions for the first sponsor meeting | C12: No | D12: 2 | E12: Molly Tran
A13: 1.2.3 | B13: Sponsor meeting Oct 7: current process and sample data | C13: No | D13: 4 | E13: All team
A14: 1.2.4 | B14: Sponsor meeting Oct 14: scope narrowed to import, one dataset and queries | C14: No | D14: 4 | E14: All team
A15: 1.2.5 | B15: Write up meeting notes and action items | C15: No | D15: 2 | E15: Molly Tran
A16: 1.2.6 | B16: Map the GPSRC data process and the Data Project template columns | C16: No | D16: 3 | E16: Molly Tran
A17: 1.3 | B17: SWE 277P Assignment 2: MOV (due Oct 13) | C17: Yes | D17: =SUM(D18:D21) -> 6
A18: 1.3.1 | B18: Six-step MOV draft: impact, value, metric, time frame | C18: No | D18: 2 | E18: Molly Tran
A19: 1.3.2 | B19: Explain how the MOV supports GPSRC's vision and mission | C19: No | D19: 2 | E19: Jennifer Sun
A20: 1.3.3 | B20: Discuss the MOV with the sponsor and record the outcome | C20: No | D20: 1 | E20: Molly Tran
A21: 1.3.4 | B21: Review and submit | C21: No | D21: 1 | E21: Brandon Lau
A22: 1.4 | B22: SWE 276P: Project Scope and High-Level Design report (due Oct 16) | C22: Yes | D22: =SUM(D23:D28) -> 18
A23: 1.4.1 | B23: Project overview, target users and stakeholders | C23: No | D23: 2 | E23: Jennifer Sun
A24: 1.4.2 | B24: Scope definition: boundaries, P0/P1/P2 features, assumptions | C24: No | D24: 4 | E24: Zhenyu Song
A25: 1.4.3 | B25: C4 context, container and component diagrams | C25: No | D25: 4 | E25: Zhenyu Song
A26: 1.4.4 | B26: Data model and import sequence diagrams | C26: No | D26: 3 | E26: Brandon Lau
A27: 1.4.5 | B27: Technology stack and design rationale | C27: No | D27: 3 | E27: Zhenyu Song
A28: 1.4.6 | B28: Edit, format as PDF and submit | C28: No | D28: 2 | E28: Molly Tran
A29: 1.5 | B29: Technology ramp-up | C29: No | D29: =SUM(D30:D33) -> 12
A30: 1.5.1 | B30: PostgreSQL, Alembic, Docker Compose and nginx | C30: No | D30: 3 | E30: Brandon Lau
A31: 1.5.2 | B31: React, MUI and TanStack Query | C31: No | D31: 3 | E31: Jennifer Sun
A32: 1.5.3 | B32: LangGraph, text-to-SQL and the LLM provider APIs | C32: No | D32: 3 | E32: Zhenyu Song
A33: 1.5.4 | B33: FastAPI and reading CSV and Excel exports | C33: No | D33: 3 | E33: Molly Tran
A34: 1.6 | B34: SWE 277P Assignment 3: Business Case (due Oct 20) | C34: Yes | D34: =SUM(D35:D38) -> 8
A35: 1.6.1 | B35: Executive summary and introduction | C35: No | D35: 2 | E35: Brandon Lau
A36: 1.6.2 | B36: Alternatives and their analysis (TCO, TBO, feasibility, risk) | C36: No | D36: 3 | E36: Jennifer Sun
A37: 1.6.3 | B37: Scoring model and recommendation | C37: No | D37: 2 | E37: Molly Tran
A38: 1.6.4 | B38: Final consistency check and submit | C38: No | D38: 1 | E38: Zhenyu Song
A39: 1.7 | B39: SWE 277P Assignment 4: Project Charter (due Oct 20) | C39: Yes | D39: =SUM(D40:D43) -> 7
A40: 1.7.1 | B40: Stakeholder table, project description and MOV | C40: No | D40: 2 | E40: Brandon Lau
...

Sheet Effort Summary
A1: Effort by person and sprint (person-hours)
A2: Computed from the WBS sheet. Rows owned by "All team" are split evenly across the four members.
A4: Assumptions (blue = input)
A5: Team members | B5: 4
A6: Hours per person per week (project charter) | B6: 10
A8: Person | B8: Role | C8: Sprint 0 | D8: Sprint 1 | E8: Sprint 2 | F8: Sprint 3 | G8: Total
A9: Brandon Lau | B9: Database / DevOps | C9: =SUMIFS(WBS!$D$4:$D$49,WBS!$E$4:$E$49,$A9)+SUMIFS(WBS!$D$4:$D$49,WBS!$E$4:$E$49,"All team")/$B$5 -> 24 | D9: =SUMIFS(WBS!$D$51:$D$131,WBS!$E$51:$E$131,$A9)+SUMIFS(WBS!$D$51:$D$131,WBS!$E$51:$E$131,"All team")/$B$5 -> 26 | E9: =SUMIFS(WBS!$D$133:$D$190,WBS!$E$133:$E$190,$A9)+SUMIFS(WBS!$D$133:$D$190,WBS!$E$133:$E$190,"All team")/$B$5 -> 21 | F9: =SUMIFS(WBS!$D$192:$D$241,WBS!$E$192:$E$241,$A9)+SUMIFS(WBS!$D$192:$D$241,WBS!$E$192:$E$241,"All team")/$B$5 -> 31 | G9: =SUM(C9:F9) -> 102
A10: Jennifer Sun | B10: Frontend | C10: =SUMIFS(WBS!$D$4:$D$49,WBS!$E$4:$E$49,$A10)+SUMIFS(WBS!$D$4:$D$49,WBS!$E$4:$E$49,"All team")/$B$5 -> 27 | D10: =SUMIFS(WBS!$D$51:$D$131,WBS!$E$51:$E$131,$A10)+SUMIFS(WBS!$D$51:$D$131,WBS!$E$51:$E$131,"All team")/$B$5 -> 29 | E10: =SUMIFS(WBS!$D$133:$D$190,WBS!$E$133:$E$190,$A10)+SUMIFS(WBS!$D$133:$D$190,WBS!$E$133:$E$190,"All team")/$B$5 -> 20 | F10: =SUMIFS(WBS!$D$192:$D$241,WBS!$E$192:$E$241,$A10)+SUMIFS(WBS!$D$192:$D$241,WBS!$E$192:$E$241,"All team")/$B$5 -> 26 | G10: =SUM(C10:F10) -> 102
A11: Molly Tran | B11: Backend / Data Import | C11: =SUMIFS(WBS!$D$4:$D$49,WBS!$E$4:$E$49,$A11)+SUMIFS(WBS!$D$4:$D$49,WBS!$E$4:$E$49,"All team")/$B$5 -> 32 | D11: =SUMIFS(WBS!$D$51:$D$131,WBS!$E$51:$E$131,$A11)+SUMIFS(WBS!$D$51:$D$131,WBS!$E$51:$E$131,"All team")/$B$5 -> 29 | E11: =SUMIFS(WBS!$D$133:$D$190,WBS!$E$133:$E$190,$A11)+SUMIFS(WBS!$D$133:$D$190,WBS!$E$133:$E$190,"All team")/$B$5 -> 16 | F11: =SUMIFS(WBS!$D$192:$D$241,WBS!$E$192:$E$241,$A11)+SUMIFS(WBS!$D$192:$D$241,WBS!$E$192:$E$241,"All team")/$B$5 -> 26 | G11: =SUM(C11:F11) -> 103
A12: Zhenyu Song | B12: AI / Chatbot | C12: =SUMIFS(WBS!$D$4:$D$49,WBS!$E$4:$E$49,$A12)+SUMIFS(WBS!$D$4:$D$49,WBS!$E$4:$E$49,"All team")/$B$5 -> 26 | D12: =SUMIFS(WBS!$D$51:$D$131,WBS!$E$51:$E$131,$A12)+SUMIFS(WBS!$D$51:$D$131,WBS!$E$51:$E$131,"All team")/$B$5 -> 36 | E12: =SUMIFS(WBS!$D$133:$D$190,WBS!$E$133:$E$190,$A12)+SUMIFS(WBS!$D$133:$D$190,WBS!$E$133:$E$190,"All team")/$B$5 -> 18 | F12: =SUMIFS(WBS!$D$192:$D$241,WBS!$E$192:$E$241,$A12)+SUMIFS(WBS!$D$192:$D$241,WBS!$E$192:$E$241,"All team")/$B$5 -> 23 | G12: =SUM(C12:F12) -> 103
A13: Total | C13: =SUM(C9:C12) -> 109 | D13: =SUM(D9:D12) -> 120 | E13: =SUM(E9:E12) -> 75 | F13: =SUM(F9:F12) -> 106 | G13: =SUM(G9:G12) -> 410
A14: Check: sum of the WBS task rows | C14: =SUMIFS(WBS!$D$4:$D$49,WBS!$E$4:$E$49,"<>") -> 109 | D14: =SUMIFS(WBS!$D$51:$D$131,WBS!$E$51:$E$131,"<>") -> 120 | E14: =SUMIFS(WBS!$D$133:$D$190,WBS!$E$133:$E$190,"<>") -> 75 | F14: =SUMIFS(WBS!$D$192:$D$241,WBS!$E$192:$E$241,"<>") -> 106 | G14: =SUM(C14:F14) -> 410
A15: Weeks in the sprint | C15: 3.5 | D15: 2 | E15: 2 | F15: 2.5 | G15: =SUM(C15:F15) -> 10
A16: Capacity (weeks × members × hours per week) | C16: =C15*$B$5*$B$6 -> 140 | D16: =D15*$B$5*$B$6 -> 80 | E16: =E15*$B$5*$B$6 -> 80 | F16: =F15*$B$5*$B$6 -> 100 | G16: =G15*$B$5*$B$6 -> 400
A17: Load (planned ÷ capacity) | C17: =IF(C16=0,0,C13/C16) -> 0.77857143 | D17: =IF(D16=0,0,D13/D16) -> 1.5 | E17: =IF(E16=0,0,E13/E16) -> 0.9375 | F17: =IF(F16=0,0,F13/F16) -> 1.06 | G17: =IF(G16=0,0,G13/G16) -> 1.025
A19: Notes
A20: Estimated Time is in person-hours of human work: planning, specifying, reviewing AI-generated code, testing and writing.
A21: Sprint 1 is over capacity on purpose: the MVP the charter planned for weeks 5–9 was built in Sprint 1 with AI-assisted development.
A22: Sprints 2 and 3 use the time this freed for the backlog (docs/backlog.md) and the handoff items (docs/handoff.md).
A23: The post-capstone backlog at the end of the WBS sheet is not counted here.
A24: From Sprint 2 on, the WBS gets an Actual Time column filled from the team's time log.
